Workbook

Sheet Dashboard Config
A1: DASHBOARD CONFIG — MTN Ghana
A2: Controls dashboard elements. Edit Value column to customise; delete a row to fall back to auto-selection.
A4: Setting Key | B4: Value | C4: Section | D4: Description
A5: TAB 04: SUMMARY TILES
A6: tile_1_kpi | B6: FIN01 | C6: TAB 04 | D6: KPI for tile 1 — default: Service Revenue
A7: tile_2_kpi | B7: FIN03 | C7: TAB 04 | D7: KPI for tile 2 — default: EBITDA margin
A8: tile_3_kpi | B8: SEG02 | C8: TAB 04 | D8: KPI for tile 3 — default: Data share of revenue
A9: tile_4_kpi | B9: OPS08 | C9: TAB 04 | D9: KPI for tile 4 — default: Avg ARPU GHS
A10: TAB 04: WATERFALLS
A11: waterfall_financial_kpi | B11: FIN01 | C11: TAB 04 | D11: Financial waterfall anchor
A12: waterfall_nonfinancial_kpi | B12: OPS08 | C12: TAB 04 | D12: Non-financial waterfall anchor (ARPU)
A13: TAB 05: COMPARISON CHARTS
A14: compare_financial_kpis | B14: FIN01,FIN02,FIN03,FIN04,FIN05,FIN08,FIN10,FIN11,FIN13 | C14: TAB 05 | D14: Financial KPIs for comparison bar chart
A15: compare_nonfinancial_kpis | B15: OPS01,OPS02,OPS04,OPS05,OPS06,OPS08,SEG01,SEG02,SEG03,SEG04,LED01,LED03 | C15: TAB 05 | D15: Non-financial KPIs for comparison bar chart
A16: TAB 06: REVERSE STRESS
A17: reverse_default_kpi | B17: FIN03 | C17: TAB 06 | D17: Default KPI on reverse stress tab
A18: reverse_default_target | B18: 55.0 | C18: TAB 06 | D18: Default target value (EBITDA margin floor)
A19: reverse_default_scenario | B19: S11 | C19: TAB 06 | D19: Default scenario (Ghana macro reversal)
A20: UNIT FORMATS
A21: format_GHSm | B21: GHS#.#m | C21: UNIT FORMATS | D21: Ghana Cedi millions
A22: format_GHS | B22: GHS#.## | C22: UNIT FORMATS | D22: Ghana Cedi (per unit)
A23: format_USD | B23: $#.## | C23: UNIT FORMATS | D23: US Dollar
A24: format_% | B24: #.#% | C24: UNIT FORMATS | D24: Percentage
A25: format_m | B25: #.#m | C25: UNIT FORMATS | D25: Millions of users/subs
A26: format_GB | B26: #.#GB | C26: UNIT FORMATS | D26: Gigabytes
A27: format_count | B27: # | C27: UNIT FORMATS | D27: Count
A28: format_bps | B28: #.# bps | C28: UNIT FORMATS | D28: Basis points
A29: format_x | B29: #.##x | C29: UNIT FORMATS | D29: Multiplier
A30: format_pp | B30: #.#pp | C30: UNIT FORMATS | D30: Percentage points
A31: format_index | B31: # | C31: UNIT FORMATS | D31: Index value
A32: format_days | B32: # days | C32: UNIT FORMATS | D32: Days
A33: format_GHS/USD | B33: #.## | C33: UNIT FORMATS | D33: Cedi-USD exchange rate
A34: SHEET NAMES
A35: sheet_kri_register | B35: KRI Register | C35: SHEET NAMES | D35: Sheet name for KRI register
A36: sheet_base_case | B36: Base Case | C36: SHEET NAMES | D36: Sheet name for base case
A37: sheet_scenarios | B37: Scenario Library | C37: SHEET NAMES | D37: Sheet name for scenarios
A38: BRANDING
A39: report_title | B39: MTN GHANA — FY25 KRI Dashboard | C39: BRANDING | D39: Title in header
A40: report_period | B40: FY 2025 | C40: BRANDING | D40: Period label
A41: framework_version | B41: v8.0 | C41: BRANDING | D41: Framework version
...

Sheet Data Quality
A1: DATA QUALITY MONITOR — MTN Ghana
A2: Live validation across all source sheets. Resolve all RED items before relying on the dashboard.
A4: Check | B4: Sheet | C4: Result | D4: Count | E4: Severity | F4: Action if failing
A5: BASE CASE
A6: Invalid KPI IDs (must be uppercase) | B6: Base Case | C6: =IF(D6=0,"OK","FAIL") -> OK | D6: =SUMPRODUCT((LEN('Base Case'!A5:A100)>0)*((EXACT('Base Case'!A5:A100,UPPER('Base Case'!A5:A100))=FALSE())+(ISNUMBER(SEARCH(" ",'Base Case'!A5:A100))*1)>0)) -> 0 | E6: BLOCKER | F6: KPI IDs must be uppercase letters + digits (e.g. FIN01, OPS21). Lowercase or spaces break references.
A7: Duplicate KPI IDs | B7: Base Case | C7: =IF(D7=0,"OK","FAIL") -> OK | D7: =SUMPRODUCT((COUNTIF('Base Case'!A5:A100,'Base Case'!A5:A100)>1)*(LEN('Base Case'!A5:A100)>0)) -> 0 | E7: BLOCKER | F7: Each KPI ID must be unique.
A8: Non-numeric base values | B8: Base Case | C8: =IF(D8=0,"OK","FAIL") -> OK | D8: =SUMPRODUCT((LEN('Base Case'!A5:A100)>0)*(ISNUMBER('Base Case'!E5:E100)=FALSE())) -> 0 | E8: BLOCKER | F8: Base values must be numeric.
A9: Missing units | B9: Base Case | C9: =IF(D9=0,"OK","FAIL") -> OK | D9: =SUMPRODUCT((LEN('Base Case'!A5:A100)>0)*(LEN('Base Case'!F5:F100)=0)) -> 0 | E9: WARN | F9: Without a unit, values fall back to plain numbers in formatting.
A10: SCENARIO LIBRARY
A11: Orphan KPI references (not in Base Case) | B11: Scenario Library | C11: =IF(D11=0,"OK","FAIL") -> OK | D11: =SUMPRODUCT((LEN('Scenario Library'!E5:E200)>0)*(ISERROR(MATCH('Scenario Library'!E5:E200,'Base Case'!A5:A100,0))*1)) -> 0 | E11: BLOCKER | F11: KPI IDs in scenario impacts must exist in Base Case.
A12: Invalid impact types | B12: Scenario Library | C12: =IF(D12=0,"OK","FAIL") -> OK | D12: =SUMPRODUCT((LEN('Scenario Library'!F5:F200)>0)*(('Scenario Library'!F5:F200<>"pct")*('Scenario Library'!F5:F200<>"delta")*('Scenario Library'!F5:F200<>"abs"))) -> 0 | E12: BLOCKER | F12: Impact type must be 'pct', 'delta', or 'abs' (or a custom type defined in Dashboard Config).
A13: Non-numeric impact values | B13: Scenario Library | C13: =IF(D13=0,"OK","FAIL") -> OK | D13: =SUMPRODUCT((LEN('Scenario Library'!E5:E200)>0)*(ISNUMBER('Scenario Library'!G5:G200)=FALSE())) -> 0 | E13: BLOCKER | F13: Impact values must be numeric.
A14: FILE & SHEET INTEGRITY
A15: Required sheets missing | B15: Workbook | C15: =IF(D15=0,"OK","FAIL") -> OK | D15: =IF(ISREF('KRI Register'!A1),0,1)+IF(ISREF('Base Case'!A1),0,1)+IF(ISREF('Scenario Library'!A1),0,1)+IF(ISREF('Dashboard Config'!A1),0,1) -> 0 | E15: BLOCKER | F15: A required sheet has been renamed or deleted.
A16: Ghana data sheets present | B16: Workbook | C16: =IF(D16=0,"OK","FAIL") -> OK | D16: =IF(ISREF(Annual!A1),0,1)+IF(ISREF(Operational_Annual!A1),0,1)+IF(ISREF(Segments_Annual!A1),0,1)+IF(ISREF(Leading_Indicators!A1),0,1)+IF(ISREF(Macro_Context!A1),0,1) -> 0 | E16: WARN | F16: Underlying Ghana datasets — without these, Base Case lookups break.
A17: Config keys missing | B17: Dashboard Config | C17: =IF(D17=0,"OK","FAIL") -> OK | D17: =IF(ISERROR(VLOOKUP("expected_kri_filename",'Dashboard Config'!A:B,2,FALSE())),1,0)+IF(ISERROR(VLOOKUP("autodetect_mode",'Dashboard Config'!A:B,2,FALSE())),1,0)+IF(ISERROR(VLOOKUP("report_title",'Dashboard Config'!A:B,2,FALSE())),1,0) -> 0 | E17: WARN | F17: Key configuration settings missing — dashboard may use built-in defaults.
A18: SUMMARY
A19: Total BLOCKER issues | C19: =IF(D19=0,"DASHBOARD READY","ISSUES FOUND") -> DASHBOARD READY | D19: =SUMPRODUCT((E5:E18="BLOCKER")*D5:D18) -> 0
A20: Total WARN issues | C20: =IF(D20=0,"NO WARNINGS","WARNINGS") -> NO WARNINGS | D20: =SUMPRODUCT((E5:E18="WARN")*D5:D18) -> 0

Sheet KRI Register
A1: # | B1: Risk Category | C1: Sub-risk / Theme | D1: KRI | E1: Type | F1: Unit | G1: Frequency | H1: Owner | I1: GREEN threshold | J1: AMBER threshold | K1: RED threshold | L1: FY25 Actual / Latest | M1: RAG Status | N1: Trend vs PY | O1: Data source | P1: Mitigation / Response
A2: 1 | B2: Financial | C2: Financial | D2: Service Revenue Growth YoY | E2: Lagging | F2: % | G2: Quarterly | H2: Risk Manager | I2: >25 | J2: 15-25 | K2: <15 | L2: 36.2 | M2: Amber | N2: → | O2: Annual.Service_Rev_Growth_Pct | P2: Standard mitigation set
A3: 2 | B3: Financial | C3: Financial | D3: EBITDA Margin | E3: Lagging | F3: % | G3: Quarterly | H3: Risk Manager | I3: >55 | J3: 50-55 | K3: <50 | L3: 60.1 | M3: Amber | N3: → | O3: Annual.EBITDA_Margin_Pct | P3: Standard mitigation set
A4: 3 | B4: Financial | C4: Financial | D4: EBITDA Growth YoY | E4: Lagging | F4: % | G4: Quarterly | H4: Risk Manager | I4: >25 | J4: 15-25 | K4: <15 | L4: 43.5 | M4: Amber | N4: → | O4: Annual.EBITDA_Growth_Pct | P4: Standard mitigation set
A5: 4 | B5: Financial | C5: Financial | D5: PAT Growth YoY | E5: Lagging | F5: % | G5: Quarterly | H5: Risk Manager | I5: >30 | J5: 20-30 | K5: <20 | L5: 55.9 | M5: Amber | N5: → | O5: Annual.PAT_Growth_Pct | P5: Standard mitigation set
A6: 5 | B6: Financial | C6: Financial | D6: PAT Margin | E6: Lagging | F6: % | G6: Quarterly | H6: Risk Manager | I6: >25 | J6: 20-25 | K6: <20 | L6: 32 | M6: Amber | N6: → | O6: Annual.PAT_Margin_Pct | P6: Standard mitigation set
A7: 6 | B7: Financial | C7: Financial | D7: Cost vs Revenue Growth Ratio | E7: Lagging | F7: % | G7: Quarterly | H7: Risk Manager | I7: <80 | J7: 80-100 | K7: >100 | L7: — | M7: Amber | N7: → | O7: Derived_Ratios.Cost_Revenue_Ratio | P7: Standard mitigation set
A8: 7 | B8: Financial | C8: Financial | D8: Capex Intensity | E8: Lagging | F8: % | G8: Quarterly | H8: Risk Manager | I8: 20-25 | J8: 15-20 or 25-30 | K8: <15 or >30 | L8: 22.7 | M8: Amber | N8: → | O8: Annual.Capex_Intensity_Pct | P8: Standard mitigation set
A9: 8 | B9: Financial | C9: Financial | D9: EPS Growth YoY | E9: Lagging | F9: % | G9: Quarterly | H9: Risk Manager | I9: >30 | J9: 20-30 | K9: <20 | L9: 55.9 | M9: Amber | N9: → | O9: Annual.EPS_Growth_Pct | P9: Standard mitigation set
A10: 9 | B10: Strategic | C10: Segment | D10: Data Revenue Growth | E10: Lagging | F10: % | G10: Quarterly | H10: Risk Manager | I10: >40 | J10: 25-40 | K10: <25 | L10: 6.9 | M10: Amber | N10: → | O10: Segments_Annual.Data_Growth_Pct | P10: Standard mitigation set
A11: 10 | B11: Strategic | C11: Segment | D11: Data Share of Revenue | E11: Lagging | F11: % | G11: Quarterly | H11: Risk Manager | I11: >50 | J11: 45-50 | K11: <45 | L11: 52.6 | M11: Amber | N11: → | O11: Segments_Annual.Data_Share_Pct | P11: Standard mitigation set
A12: 11 | B12: Strategic | C12: Segment | D12: MoMo Revenue Growth | E12: Lagging | F12: % | G12: Quarterly | H12: Risk Manager | I12: >35 | J12: 20-35 | K12: <20 | L12: -7.5 | M12: Amber | N12: → | O12: Segments_Annual.MoMo_Growth_Pct | P12: Standard mitigation set
A13: 12 | B13: Strategic | C13: Segment | D13: MoMo Share of Revenue | E13: Lagging | F13: % | G13: Quarterly | H13: Risk Manager | I13: >24 | J13: 20-24 | K13: <20 | L13: 24.6 | M13: Amber | N13: → | O13: Segments_Annual.MoMo_Share_Pct | P13: Standard mitigation set
A14: 13 | B14: Strategic | C14: Segment | D14: Voice Revenue Growth | E14: Lagging | F14: % | G14: Quarterly | H14: Risk Manager | I14: >5 | J14: -5 to 5 | K14: <-5 | L14: 7.5 | M14: Amber | N14: → | O14: Segments_Annual.Voice_Growth_Pct | P14: Standard mitigation set
A15: 14 | B15: Strategic | C15: Segment | D15: Digital Revenue Growth | E15: Lagging | F15: % | G15: Quarterly | H15: Risk Manager | I15: >50 | J15: 30-50 | K15: <30 | L15: -45.7 | M15: Amber | N15: → | O15: Segments_Annual.Digital_Growth_Pct | P15: Standard mitigation set
A16: 15 | B16: Strategic | C16: Segment | D16: Digital Share of Revenue | E16: Lagging | F16: % | G16: Quarterly | H16: Risk Manager | I16: >2 | J16: 1-2 | K16: <1 | L16: 1.7 | M16: Amber | N16: → | O16: Segments_Annual.Digital_Share_Pct | P16: Standard mitigation set
A17: 16 | B17: Operational | C17: Operational | D17: Subscriber Growth YoY | E17: Lagging | F17: % | G17: Quarterly | H17: Risk Manager | I17: >5 | J17: 2-5 | K17: <2 | L17: 9.5 | M17: Amber | N17: → | O17: Operational_Annual.Subs_Growth_Pct | P17: Standard mitigation set
A18: 17 | B18: Operational | C18: Operational | D18: Data Subscriber Growth | E18: Lagging | F18: % | G18: Quarterly | H18: Risk Manager | I18: >10 | J18: 5-10 | K18: <5 | L18: 13.7 | M18: Amber | N18: → | O18: Operational_Annual.Data_Subs_Growth_Pct | P18: Standard mitigation set
A19: 18 | B19: Operational | C19: Operational | D19: MoMo User Growth | E19: Lagging | F19: % | G19: Quarterly | H19: Risk Manager | I19: >10 | J19: 5-10 | K19: <5 | L19: 12.2 | M19: Amber | N19: → | O19: Operational_Annual.MoMo_Growth_Pct | P19: Standard mitigation set
... A27: 26 | B27: Operational | C27: Leading | D27: Working Capital Days | E27: Leading | F27: days | G27: Quarterly | H27: Risk Manager | I27: <30 | J27: 30-40 | K27: >40 | L27: 25 | M27: Amber | N27: → | O27: Leading_Indicators.Working_Capital_Days | P27: Standard mitigation set
A28: 27 | B28: Operational | C28: Leading | D28: Cedi-USD Stability | E28: Leading | F28: %_chg | G28: Quarterly | H28: Risk Manager | I28: <10 | J28: 10-20 | K28: >20 | L28: — | M28: Amber | N28: → | O28: Macro_Context.Cedi_USD_YoY_Change | P28: Standard mitigation set
A29: 28 | B29: Operational | C29: Leading | D29: Inflation YoY | E29: Leading | F29: % | G29: Quarterly | H29: Risk Manager | I29: <15 | J29: 15-25 | K29: >25 | L29: 5.4 | M29: Amber | N29: → | O29: Macro_Context.Inflation_YoY_Pct | P29: Standard mitigation set

Sheet Base Case
A1: MTN GHANA — FY25 BASE CASE KPIs
A2: Baseline values used as the starting point for all stress, shock and combined scenarios. Sourced from FY25 Annual / Operational / Segments sheets.
A4: KPI ID | B4: Category | C4: KPI | D4: Type | E4: FY25 Base Value | F4: Unit | G4: Direction (improvement) | H4: Notes
A5: FIN01 | B5: Financial | C5: Service revenue (GHSm) | D5: Lagging | E5: 24400 | F5: GHSm | G5: higher | H5: FY25 audited
A6: FIN02 | B6: Financial | C6: EBITDA (GHSm) | D6: Lagging | E6: 14700 | F6: GHSm | G6: higher | H6: FY25 audited
A7: FIN03 | B7: Financial | C7: EBITDA margin (%) | D7: Lagging | E7: 60.1 | F7: % | G7: higher | H7: FY25 — expanded from 57.1% in FY24
A8: FIN04 | B8: Financial | C8: PAT (GHSm) | D8: Lagging | E8: 7800 | F8: GHSm | G8: higher | H8: FY25 audited profit after tax
A9: FIN05 | B9: Financial | C9: PAT margin (%) | D9: Lagging | E9: 32 | F9: % | G9: higher | H9: FY25
A10: FIN06 | B10: Financial | C10: Service revenue growth YoY (%) | D10: Lagging | E10: 36.2 | F10: % | G10: higher | H10: FY25 vs FY24 audited
A11: FIN07 | B11: Financial | C11: EBITDA growth YoY (%) | D11: Lagging | E11: 43.5 | F11: % | G11: higher | H11: FY25 vs FY24
A12: FIN08 | B12: Financial | C12: EPS (GHS) | D12: Lagging | E12: 0.5923 | F12: GHS | G12: higher | H12: FY25 audited
A13: FIN09 | B13: Financial | C13: Dividend per share (GHS) | D13: Lagging | E13: 0.48 | F13: GHS | G13: higher | H13: FY25
A14: FIN10 | B14: Financial | C14: Capex (GHSm) | D14: Leading | E14: 5545 | F14: GHSm | G14: higher | H14: FY25 — supporting infrastructure investment
A15: FIN11 | B15: Financial | C15: Capex intensity (%) | D15: Leading | E15: 22.7 | F15: % | G15: higher | H15: Capex / revenue, FY25
A16: FIN12 | B16: Financial | C16: Total assets (GHSm) | D16: Lagging | E16: 49500 | F16: GHSm | G16: higher | H16: FY25 balance sheet
... A44: EXT06 | B44: External | C44: Mobile penetration (%) | D44: Leading | E44: 151 | F44: % | G44: higher | H44: Market context

Sheet Scenario Library
A1: SCENARIO LIBRARY — Stress, Shock, Reverse & Combined (Ghana-calibrated)
A2: Each scenario defines impact multipliers / deltas on Base Case KPIs.
A4: Scenario ID | B4: Type | C4: Scenario | D4: Description | E4: KPI ID | F4: Impact type | G4: Impact value | H4: Plausibility (1-5) | I4: Severity (1-5) | J4: Recovery (qtrs) | K4: Mitigation lever
A5: S01 | B5: Stress | C5: Cedi devaluation -25% | D5: Ghana Cedi depreciates 25% vs USD sustained 12 months — reverses FY25 tailwind | E5: FIN01 | F5: pct | G5: -8 | H5: 3 | I5: 4 | J5: 6 | K5: Naturally-hedge USD payables; accelerate USD pricing; renegotiate tower lease escalators
E6: FIN02 | F6: pct | G6: -12
E7: FIN03 | F7: delta | G7: -2.5
E8: EXT03 | F8: pct | G8: 25
E9: EXT04 | F9: delta | G9: -45
E10: EXT01 | F10: delta | G10: 10
E11: OPS08 | F11: pct | G11: -15
E12: FIN10 | F12: pct | G12: -15
A13: S02 | B13: Stress | C13: Inflation resurgence to 25% | D13: Macro deterioration: inflation back to 23%+, policy rate to 28%, consumer purchasing power erodes | E13: EXT01 | F13: abs | G13: 25 | H13: 3 | I13: 3 | J13: 5 | K13: Tariff increases timed with regulator; cost-out programme; postpaid mix shift
E14: EXT02 | F14: abs | G14: 28
E15: EXT05 | F15: delta | G15: -3
E16: FIN03 | F16: delta | G16: -3
E17: FIN13 | F17: pct | G17: 18
E18: OPS08 | F18: pct | G18: -8
E19: OPS01 | F19: pct | G19: -2
A20: S03 | B20: Stress | C20: MoMo regulatory tightening | D20: E-levy raised back to 1.5%, BoG caps transaction limits, agent commissions capped | E20: SEG03 | F20: pct | G20: -25 | H20: 3 | I20: 4 | J20: 6 | K20: Tier-down product portfolio; cross-border remittance focus; lobby for proportionate regulation
E21: SEG04 | F21: delta | G21: -5
E22: OPS04 | F22: pct | G22: -15
E23: LED04 | F23: pct | G23: -30
E24: FIN02 | F24: pct | G24: -4
A25: S04 | B25: Stress | C25: Sovereign debt distress / repatriation freeze | D25: Ghana sovereign credit deterioration; BoG restricts FX repatriation; dividend upstreaming blocked | E25: FIN09 | F25: pct | G25: -50 | H25: 2 | I25: 4 | J25: 8 | K25: Local-currency funding; capital-equipment imports; dividend smoothing
E26: LED06 | F26: delta | G26: 15
E27: FIN12 | F27: pct | G27: -3
E28: EXT02 | F28: delta | G28: 6
E29: FIN10 | F29: pct | G29: -20
A30: S05 | B30: Stress | C30: Energy cost shock | D30: Electricity tariff +40% sustained; ECG load-shedding intensifies; diesel costs rise | E30: FIN13 | F30: pct | G30: 12 | H30: 3 | I30: 3 | J30: 4 | K30: Solar/hybrid site rollout; PPAs with IPPs; battery hardening
E31: FIN03 | F31: delta | G31: -2
E32: LED02 | F32: delta | G32: 8
E33: OPS06 | F33: delta | G33: -0.5
A34: S06 | B34: Shock | C34: Major cyber breach — 5-day MoMo outage | D34: Sev-1 ransomware attack on MoMo platform; 5-day customer-facing outage; data exfiltration | E34: LED01 | F34: delta | G34: 8 | H34: 2 | I34: 5 | J34: 3 | K34: Incident response retainer; cyber-insurance activation; BCM plan; regulator/BoG notifications
E35: SEG03 | F35: pct | G35: -12
E36: OPS04 | F36: pct | G36: -8
E37: FIN02 | F37: pct | G37: -3
E38: LED06 | F38: delta | G38: 10
A39: S07 | B39: Shock | C39: Spectrum licence dispute | D39: NCA disputes spectrum renewal terms; service degradation in 4G capacity-constrained areas | E39: OPS06 | F39: delta | G39: -2.5 | H39: 2 | I39: 4 | J39: 6 | K39: Engage NCA pre-emptively; co-build with sector peers; tech-neutral licensing
E40: OPS05 | F40: pct | G40: -15
E41: LED02 | F41: delta | G41: 10
...

Sheet README
A1: Field | B1: Description
A2: Database Name | B2: MTN Ghana KRI Database
A3: Coverage Period | B3: Q1 2020 – Q4 2025
A4: Reporting Entity | B4: Scancom PLC (MTN Ghana) — Ghana Stock Exchange: MTNGH
A5: Data Sources | B5: MTN Ghana H1/FY published results, MTN Group quarterly trading updates, GSE filings
A6: Last Updated | B6: 2026-05-19
A7: Currency | B7: GHS millions (financial) | millions (subscribers) | GB (data usage)
A8: Sheets | B8: 1.README | 2.Quarterly | 3.HalfYearly | 4.Annual | 5.Segments_Quarterly | 6.Segments_Annual | 7.Operational_Quarterly | 8.Operational_Annual | 9.Leading_Indicators | 10.Thresholds | 11.Macro_Context | 12.Derived_Ratios
A9: Flag Legend | B9: R=Reported | I=Interpolated | E=Estimated | P=Proxy
A10: Primary Key | B10: Period_ID (e.g. 2025Q4 | C10: 2025H2 | D10: 2025FY)
A11: HTML Build Note | B11: All numeric fields are pure numbers (no thousand separators) for direct JSON conversion

Sheet Annual
A1: Period_ID | B1: Year | C1: Period_Type | D1: Service_Revenue | E1: Service_Revenue_Flag | F1: Service_Rev_Growth_Pct | G1: EBITDA | H1: EBITDA_Flag | I1: EBITDA_Growth_Pct | J1: EBITDA_Margin_Pct | K1: PAT | L1: PAT_Flag | M1: PAT_Growth_Pct | N1: PAT_Margin_Pct | O1: EPS_GHS | P1: EPS_Growth_Pct | Q1: Total_Opex | R1: Capex | S1: Capex_Intensity_Pct | T1: Dividend_Per_Share_GHS | U1: Total_Assets | V1: Total_Liabilities
A2: 2020FY | B2: 2020 | C2: Annual | D2: 6430 | E2: R | G2: 3520 | H2: R | J2: 54.7 | K2: 1460 | L2: R | N2: 22.7 | O2: 0.1108 | Q2: 3035 | R2: 1410 | S2: 21.9 | T2: 0.12 | U2: 11200 | V2: 8850
A3: 2021FY | B3: 2021 | C3: Annual | D3: 9000 | E3: R | F3: 40 | G3: 5000 | H3: R | I3: 42 | J3: 55.6 | K3: 2280 | L3: R | M3: 56.2 | N3: 25.3 | O3: 0.173 | P3: 56.1 | Q3: 4045 | R3: 1960 | S3: 21.8 | T3: 0.137 | U3: 14500 | V3: 11200
A4: 2022FY | B4: 2022 | C4: Annual | D4: 13000 | E4: R | F4: 44.4 | G4: 7400 | H4: R | I4: 48 | J4: 56.9 | K4: 3565 | L4: R | M4: 56.4 | N4: 27.4 | O4: 0.2705 | P4: 56.4 | Q4: 5910 | R4: 2630 | S4: 20.2 | T4: 0.169 | U4: 19800 | V4: 15100
A5: 2023FY | B5: 2023 | C5: Annual | D5: 17900 | E5: R | F5: 37.7 | G5: 10150 | H5: R | I5: 37.2 | J5: 56.7 | K5: 5000 | L5: R | M5: 40.3 | N5: 27.9 | O5: 0.3795 | P5: 40.3 | Q5: 8180 | R5: 3400 | S5: 19 | T5: 0.185 | U5: 28500 | V5: 21500
A6: 2024FY | B6: 2024 | C6: Annual | D6: 23900 | E6: R | F6: 33.5 | G6: 13660 | H6: R | I6: 34.6 | J6: 57.1 | K6: 6845 | L6: R | M6: 36.9 | N6: 28.6 | O6: 0.5196 | P6: 36.9 | Q6: 11240 | R6: 4880 | S6: 20.4 | T6: 0.32 | U6: 41400 | V6: 30930
A7: 2025FY | B7: 2025 | C7: Annual | D7: 24400 | E7: R | F7: 36.2 | G7: 14700 | H7: R | I7: 43.5 | J7: 60.1 | K7: 7800 | L7: R | M7: 55.9 | N7: 32 | O7: 0.5923 | P7: 55.9 | Q7: 12100 | R7: 5545 | S7: 22.7 | T7: 0.48 | U7: 49500 | V7: 36800

Sheet HalfYearly
A1: Period_ID | B1: Year | C1: Half | D1: Period_Type | E1: Service_Revenue | F1: Service_Revenue_Flag | G1: EBITDA | H1: EBITDA_Flag | I1: EBITDA_Margin_Pct | J1: EBITDA_Margin_Flag | K1: PAT | L1: PAT_Flag | M1: EPS_GHS | N1: EPS_Flag | O1: Dividend_Per_Share_GHS | P1: Dividend_Flag
A2: 2020H1 | B2: 2020 | C2: H1 | D2: Half | E2: 2970 | F2: R | G2: 1615 | H2: R | I2: 52.9 | J2: R | K2: 645 | L2: R | M2: 0.0489 | N2: R | O2: 0.04 | P2: R
A3: 2020H2 | B3: 2020 | C3: H2 | D3: Half | E3: 3460 | F3: R | G3: 1905 | H3: R | I3: 53.4 | J3: R | K3: 815 | L3: R | M3: 0.0619 | N3: R | O3: 0.08 | P3: R
A4: 2021H1 | B4: 2021 | C4: H1 | D4: Half | E4: 4135 | F4: R | G4: 2280 | H4: R | I4: 53.8 | J4: R | K4: 1025 | L4: R | M4: 0.0778 | N4: R | O4: 0.045 | P4: R
A5: 2021H2 | B5: 2021 | C5: H2 | D5: Half | E5: 4865 | F5: R | G5: 2720 | H5: R | I5: 54.3 | J5: R | K5: 1255 | L5: R | M5: 0.0952 | N5: R | O5: 0.092 | P5: R
A6: 2022H1 | B6: 2022 | C6: H1 | D6: Half | E6: 5875 | F6: R | G6: 3345 | H6: R | I6: 55.6 | J6: R | K6: 1580 | L6: R | M6: 0.1199 | N6: R | O6: 0.055 | P6: R
A7: 2022H2 | B7: 2022 | C7: H2 | D7: Half | E7: 7125 | F7: R | G7: 4055 | H7: R | I7: 55.8 | J7: R | K7: 1985 | L7: R | M7: 0.1506 | N7: R | O7: 0.114 | P7: R
A8: 2023H1 | B8: 2023 | C8: H1 | D8: Half | E8: 7800 | F8: R | G8: 4395 | H8: R | I8: 55.6 | J8: R | K8: 2155 | L8: R | M8: 0.1635 | N8: R | O8: 0.06 | P8: R
A9: 2023H2 | B9: 2023 | C9: H2 | D9: Half | E9: 10100 | F9: R | G9: 5755 | H9: R | I9: 55.7 | J9: R | K9: 2845 | L9: R | M9: 0.216 | N9: R | O9: 0.125 | P9: R
A10: 2024H1 | B10: 2024 | C10: H1 | D10: Half | E10: 10385 | F10: R | G10: 5895 | H10: R | I10: 55.5 | J10: R | K10: 2960 | L10: R | M10: 0.2247 | N10: R | O10: 0.065 | P10: R
A11: 2024H2 | B11: 2024 | C11: H2 | D11: Half | E11: 13515 | F11: R | G11: 7705 | H11: R | I11: 56.5 | J11: R | K11: 3885 | L11: R | M11: 0.2949 | N11: R | O11: 0.255 | P11: R
A12: 2025H1 | B12: 2025 | C12: H1 | D12: Half | E12: 11300 | F12: R | G12: 6600 | H12: R | I12: 58.4 | J12: R | K12: 3600 | L12: R | M12: 0.2733 | N12: R | O12: 0.08 | P12: R
A13: 2025H2 | B13: 2025 | C13: H2 | D13: Half | E13: 13100 | F13: R | G13: 8100 | H13: R | I13: 61.2 | J13: R | K13: 4200 | L13: R | M13: 0.319 | N13: R | O13: 0.4 | P13: R

Sheet Quarterly
A1: Period_ID | B1: Year | C1: Quarter | D1: Period_Type | E1: Service_Revenue | F1: Service_Revenue_Flag | G1: Total_Revenue | H1: Total_Revenue_Flag | I1: EBITDA | J1: EBITDA_Flag | K1: EBITDA_Margin_Pct | L1: EBITDA_Margin_Flag | M1: PAT | N1: PAT_Flag | O1: PAT_Margin_Pct | P1: PAT_Margin_Flag | Q1: Opex | R1: Opex_Flag | S1: Capex | T1: Capex_Flag | U1: EPS_GHS | V1: EPS_Flag
A2: 2020Q1 | B2: 2020 | C2: Q1 | D2: Quarter | E2: 1450 | F2: I | G2: 1490 | H2: I | I2: 790 | J2: I | K2: 53 | L2: I | M2: 310 | N2: I | O2: 20.8 | P2: I | Q2: 700 | R2: I | S2: 310 | T2: I | U2: 0.0235 | V2: I
A3: 2020Q2 | B3: 2020 | C3: Q2 | D3: Quarter | E3: 1520 | F3: I | G3: 1560 | H3: I | I3: 825 | J3: I | K3: 52.9 | L3: I | M3: 335 | N3: I | O3: 21.5 | P3: I | Q3: 735 | R3: I | S3: 330 | T3: I | U3: 0.0254 | V3: I
A4: 2020Q3 | B4: 2020 | C4: Q3 | D4: Quarter | E4: 1635 | F4: I | G4: 1680 | H4: I | I4: 895 | J4: I | K4: 53.3 | L4: I | M4: 375 | N4: I | O4: 22.3 | P4: I | Q4: 785 | R4: I | S4: 360 | T4: I | U4: 0.0285 | V4: I
A5: 2020Q4 | B5: 2020 | C5: Q4 | D5: Quarter | E5: 1825 | F5: I | G5: 1875 | H5: I | I5: 1010 | J5: I | K5: 53.9 | L5: I | M5: 440 | N5: I | O5: 23.5 | P5: I | Q5: 865 | R5: I | S5: 410 | T5: I | U5: 0.0334 | V5: I
A6: 2021Q1 | B6: 2021 | C6: Q1 | D6: Quarter | E6: 1985 | F6: I | G6: 2035 | H6: I | I6: 1095 | J6: I | K6: 53.8 | L6: I | M6: 490 | N6: I | O6: 24.1 | P6: I | Q6: 940 | R6: I | S6: 425 | T6: I | U6: 0.0372 | V6: I
A7: 2021Q2 | B7: 2021 | C7: Q2 | D7: Quarter | E7: 2150 | F7: I | G7: 2200 | H7: I | I7: 1185 | J7: I | K7: 53.9 | L7: I | M7: 535 | N7: I | O7: 24.3 | P7: I | Q7: 1015 | R7: I | S7: 460 | T7: I | U7: 0.0406 | V7: I
A8: 2021Q3 | B8: 2021 | C8: Q3 | D8: Quarter | E8: 2290 | F8: I | G8: 2345 | H8: I | I8: 1265 | J8: I | K8: 53.9 | L8: I | M8: 580 | N8: I | O8: 24.7 | P8: I | Q8: 1080 | R8: I | S8: 495 | T8: I | U8: 0.044 | V8: I
A9: 2021Q4 | B9: 2021 | C9: Q4 | D9: Quarter | E9: 2575 | F9: I | G9: 2640 | H9: I | I9: 1455 | J9: I | K9: 54.7 | L9: I | M9: 675 | N9: I | O9: 25.6 | P9: I | Q9: 1185 | R9: I | S9: 580 | T9: I | U9: 0.0512 | V9: I
A10: 2022Q1 | B10: 2022 | C10: Q1 | D10: Quarter | E10: 2825 | F10: I | G10: 2890 | H10: I | I10: 1605 | J10: I | K10: 55.5 | L10: I | M10: 755 | N10: I | O10: 26.1 | P10: I | Q10: 1285 | R10: I | S10: 550 | T10: I | U10: 0.0573 | V10: I
A11: 2022Q2 | B11: 2022 | C11: Q2 | D11: Quarter | E11: 3050 | F11: I | G11: 3120 | H11: I | I11: 1740 | J11: I | K11: 55.8 | L11: I | M11: 825 | N11: I | O11: 26.4 | P11: I | Q11: 1380 | R11: I | S11: 605 | T11: I | U11: 0.0626 | V11: I
A12: 2022Q3 | B12: 2022 | C12: Q3 | D12: Quarter | E12: 3320 | F12: I | G12: 3395 | H12: I | I12: 1895 | J12: I | K12: 55.8 | L12: I | M12: 910 | N12: I | O12: 26.8 | P12: I | Q12: 1500 | R12: I | S12: 675 | T12: I | U12: 0.069 | V12: I
A13: 2022Q4 | B13: 2022 | C13: Q4 | D13: Quarter | E13: 3805 | F13: I | G13: 3895 | H13: I | I13: 2160 | J13: I | K13: 55.7 | L13: I | M13: 1075 | N13: I | O13: 27.6 | P13: I | Q13: 1745 | R13: I | S13: 800 | T13: I | U13: 0.0816 | V13: I
... A25: 2025Q4 | B25: 2025 | C25: Q4 | D25: Quarter | E25: 6825 | F25: E | G25: 6985 | H25: E | I25: 4315 | J25: E | K25: 63.2 | L25: E | M25: 2190 | N25: E | O25: 32.1 | P25: E | Q25: 2510 | R25: E | S25: 1495 | T25: E | U25: 0.1665 | V25: E

Sheet Segments_Annual
A1: Period_ID | B1: Year | C1: Data_Revenue | D1: Data_Growth_Pct | E1: Data_Share_Pct | F1: Voice_Revenue | G1: Voice_Growth_Pct | H1: Voice_Share_Pct | I1: MoMo_Revenue | J1: MoMo_Growth_Pct | K1: MoMo_Share_Pct | L1: Digital_Revenue | M1: Digital_Growth_Pct | N1: Digital_Share_Pct | O1: SMS_Revenue | P1: Other_Revenue
A2: 2020FY | B2: 2020 | C2: 2125 | E2: 33 | F2: 2725 | H2: 42.4 | I2: 1017 | K2: 15.8 | L2: 61 | N2: 0.9 | O2: 220 | P2: 282
A3: 2021FY | B3: 2021 | C3: 3375 | D3: 58.8 | E3: 37.5 | F3: 3295 | G3: 20.9 | H3: 36.6 | I3: 1800 | J3: 77 | K3: 20 | L3: 114 | M3: 86.9 | N3: 1.3 | O3: 208 | P3: 208
A4: 2022FY | B4: 2022 | C4: 5660 | D4: 67.7 | E4: 43.5 | F4: 4185 | G4: 27 | H4: 32.2 | I4: 2810 | J4: 56.1 | K4: 21.6 | L4: 209 | M4: 83.3 | N4: 1.6 | O4: 200 | P4: -64
A5: 2023FY | B5: 2023 | C5: 8340 | D5: 47.3 | E5: 46.6 | F5: 4240 | G5: 1.3 | H5: 23.7 | I5: 4525 | J5: 61 | K5: 25.3 | L5: 379 | M5: 81.3 | N5: 2.1 | O5: 184 | P5: 232
A6: 2024FY | B6: 2024 | C6: 12005 | D6: 43.9 | E6: 50.2 | F6: 3740 | G6: -11.8 | H6: 15.6 | I6: 6485 | J6: 43.3 | K6: 27.1 | L6: 755 | M6: 99.2 | N6: 3.2 | O6: 160 | P6: 755
A7: 2025FY | B7: 2025 | C7: 12835 | D7: 6.9 | E7: 52.6 | F7: 4020 | G7: 7.5 | H7: 16.5 | I7: 6000 | J7: -7.5 | K7: 24.6 | L7: 410 | M7: -45.7 | N7: 1.7 | O7: 148 | P7: 987

Sheet Segments_Quarterly
A1: Period_ID | B1: Year | C1: Quarter | D1: Data_Revenue | E1: Data_Flag | F1: Voice_Revenue | G1: Voice_Flag | H1: MoMo_Revenue | I1: MoMo_Flag | J1: Digital_Revenue | K1: Digital_Flag | L1: SMS_Revenue | M1: SMS_Flag | N1: Roaming_Wholesale_Other | O1: Other_Flag
A2: 2020Q1 | B2: 2020 | C2: Q1 | D2: 460 | E2: I | F2: 635 | G2: I | H2: 210 | I2: I | J2: 12 | K2: I | L2: 55 | M2: I | N2: 78 | O2: I
A3: 2020Q2 | B3: 2020 | C3: Q2 | D3: 495 | E3: I | F3: 655 | G3: I | H3: 232 | I3: I | J3: 14 | K3: I | L3: 55 | M3: I | N3: 69 | O3: I
A4: 2020Q3 | B4: 2020 | C4: Q3 | D4: 545 | E4: I | F4: 690 | G4: I | H4: 265 | I4: I | J4: 16 | K4: I | L4: 55 | M4: I | N4: 64 | O4: I
A5: 2020Q4 | B5: 2020 | C5: Q4 | D5: 625 | E5: I | F5: 745 | G5: I | H5: 310 | I5: I | J5: 19 | K5: I | L5: 55 | M5: I | N5: 71 | O5: I
A6: 2021Q1 | B6: 2021 | C6: Q1 | D6: 710 | E6: I | F6: 790 | G6: I | H6: 365 | I6: I | J6: 22 | K6: I | L6: 52 | M6: I | N6: 46 | O6: I
A7: 2021Q2 | B7: 2021 | C7: Q2 | D7: 790 | E7: I | F7: 820 | G7: I | H7: 420 | I7: I | J7: 26 | K7: I | L7: 52 | M7: I | N7: 42 | O7: I
A8: 2021Q3 | B8: 2021 | C8: Q3 | D8: 865 | E8: I | F8: 855 | G8: I | H8: 470 | I8: I | J8: 30 | K8: I | L8: 52 | M8: I | N8: 18 | O8: I
A9: 2021Q4 | B9: 2021 | C9: Q4 | D9: 1010 | E9: I | F9: 930 | G9: I | H9: 545 | I9: I | J9: 36 | K9: I | L9: 52 | M9: I | N9: 2 | O9: I
A10: 2022Q1 | B10: 2022 | C10: Q1 | D10: 1190 | E10: I | F10: 985 | G10: I | H10: 580 | I10: I | J10: 42 | K10: I | L10: 50 | M10: I | N10: -22 | O10: I
A11: 2022Q2 | B11: 2022 | C11: Q2 | D11: 1305 | E11: I | F11: 1015 | G11: I | H11: 650 | I11: I | J11: 48 | K11: I | L11: 50 | M11: I | N11: -18 | O11: I
A12: 2022Q3 | B12: 2022 | C12: Q3 | D12: 1450 | E12: I | F12: 1055 | G12: I | H12: 725 | I12: I | J12: 54 | K12: I | L12: 50 | M12: I | N12: -14 | O12: I
A13: 2022Q4 | B13: 2022 | C13: Q4 | D13: 1715 | E13: I | F13: 1130 | G13: I | H13: 855 | I13: I | J13: 65 | K13: I | L13: 50 | M13: I | N13: -10 | O13: I
... A25: 2025Q4 | B25: 2025 | C25: Q4 | D25: 3545 | E25: E | F25: 1015 | G25: E | H25: 1655 | I25: E | J25: 115 | K25: E | L25: 36 | M25: E | N25: 459 | O25: E

Sheet Operational_Annual
A1: Period_ID | B1: Year | C1: Total_Subscribers_M | D1: Subs_Growth_Pct | E1: Active_Data_Subs_M | F1: Data_Subs_Growth_Pct | G1: Data_Penetration_Pct | H1: Active_MoMo_Users_M | I1: MoMo_Growth_Pct | J1: MoMo_Penetration_Pct | K1: Data_Usage_GB_Annual | L1: Voice_MoU_Annual | M1: 4G_Coverage_Pct | N1: Network_Sites | O1: Avg_ARPU_GHS | P1: Capex_per_Sub_GHS
A2: 2020FY | B2: 2020 | C2: 24.1 | E2: 11.4 | G2: 47.3 | H2: 12.8 | J2: 53.1 | K2: 3.6 | L2: 675 | M2: 87 | N2: 6050 | O2: 22.3 | P2: 58.5
A3: 2021FY | B3: 2021 | C3: 25.7 | D3: 6.6 | E3: 13.5 | F3: 18.4 | G3: 52.5 | H3: 14.6 | I3: 14.1 | J3: 56.8 | K3: 4.8 | L3: 665 | M3: 93 | N3: 6580 | O3: 29.2 | P3: 76.3
A4: 2022FY | B4: 2022 | C4: 26.5 | D4: 3.1 | E4: 15 | F4: 11.1 | G4: 56.6 | H4: 15.3 | I4: 4.8 | J4: 57.7 | K4: 6.1 | L4: 610 | M4: 96 | N4: 7120 | O4: 40.8 | P4: 99.2
A5: 2023FY | B5: 2023 | C5: 27.2 | D5: 2.6 | E5: 16 | F5: 6.7 | G5: 58.8 | H5: 15.7 | I5: 2.6 | J5: 57.7 | K5: 7.9 | L5: 580 | M5: 98 | N5: 7650 | O5: 54.8 | P5: 125
A6: 2024FY | B6: 2024 | C6: 28.5 | D6: 4.8 | E6: 17.5 | F6: 9.4 | G6: 61.4 | H6: 17.2 | I6: 9.6 | J6: 60.4 | K6: 9.8 | L6: 545 | M6: 99 | N6: 8170 | O6: 69.8 | P6: 171.2
A7: 2025FY | B7: 2025 | C7: 31.2 | D7: 9.5 | E7: 19.9 | F7: 13.7 | G7: 63.8 | H7: 19.3 | I7: 12.2 | J7: 61.9 | K7: 14.5 | L7: 605 | M7: 99.5 | N7: 8650 | O7: 66.9 | P7: 177.7

Sheet Operational_Quarterly
A1: Period_ID | B1: Year | C1: Quarter | D1: Total_Subscribers_M | E1: Subs_Flag | F1: Active_Data_Subs_M | G1: Data_Subs_Flag | H1: Active_MoMo_Users_M | I1: MoMo_Users_Flag | J1: Data_Usage_GB_Per_User | K1: Usage_Flag | L1: Voice_MoU_Per_User | M1: MoU_Flag | N1: 4G_Coverage_Pct | O1: Coverage_Flag | P1: Network_Sites | Q1: Sites_Flag | R1: ARPU_GHS | S1: ARPU_Flag
A2: 2020Q1 | B2: 2020 | C2: Q1 | D2: 22.6 | E2: I | F2: 9.8 | G2: I | H2: 11.2 | I2: I | J2: 3.2 | K2: I | L2: 165 | M2: I | N2: 82.5 | O2: I | P2: 5650 | Q2: I | R2: 21.4 | S2: I
A3: 2020Q2 | B3: 2020 | C3: Q2 | D3: 23.1 | E3: I | F3: 10.4 | G3: I | H3: 11.9 | I3: I | J3: 3.4 | K3: I | L3: 168 | M3: I | N3: 84 | O3: I | P3: 5780 | Q3: I | R3: 22 | S3: I
A4: 2020Q3 | B4: 2020 | C4: Q3 | D4: 23.8 | E4: I | F4: 11 | G4: I | H4: 12.5 | I4: I | J4: 3.7 | K4: I | L4: 170 | M4: I | N4: 85.5 | O4: I | P4: 5910 | Q4: I | R4: 22.9 | S4: I
A5: 2020Q4 | B5: 2020 | C5: Q4 | D5: 24.1 | E5: I | F5: 11.4 | G5: I | H5: 12.8 | I5: I | J5: 4 | K5: I | L5: 172 | M5: I | N5: 87 | O5: I | P5: 6050 | Q5: I | R5: 25.2 | S5: I
A6: 2021Q1 | B6: 2021 | C6: Q1 | D6: 24.5 | E6: I | F6: 12 | G6: I | H6: 13.3 | I6: I | J6: 4.3 | K6: I | L6: 170 | M6: I | N6: 88.5 | O6: I | P6: 6180 | Q6: I | R6: 27 | S6: I
A7: 2021Q2 | B7: 2021 | C7: Q2 | D7: 24.9 | E7: I | F7: 12.5 | G7: I | H7: 13.8 | I7: I | J7: 4.6 | K7: I | L7: 168 | M7: I | N7: 90 | O7: I | P7: 6310 | Q7: I | R7: 28.8 | S7: I
A8: 2021Q3 | B8: 2021 | C8: Q3 | D8: 25.3 | E8: I | F8: 13 | G8: I | H8: 14.2 | I8: I | J8: 4.9 | K8: I | L8: 165 | M8: I | N8: 91.5 | O8: I | P8: 6440 | Q8: I | R8: 30.2 | S8: I
A9: 2021Q4 | B9: 2021 | C9: Q4 | D9: 25.7 | E9: I | F9: 13.5 | G9: I | H9: 14.6 | I9: I | J9: 5.3 | K9: I | L9: 163 | M9: I | N9: 93 | O9: I | P9: 6580 | Q9: I | R9: 33.4 | S9: I
A10: 2022Q1 | B10: 2022 | C10: Q1 | D10: 26 | E10: I | F10: 14 | G10: I | H10: 14.9 | I10: I | J10: 5.6 | K10: I | L10: 160 | M10: I | N10: 94 | O10: I | P10: 6720 | Q10: I | R10: 36.2 | S10: I
A11: 2022Q2 | B11: 2022 | C11: Q2 | D11: 26.2 | E11: I | F11: 14.4 | G11: I | H11: 15.1 | I11: I | J11: 5.9 | K11: I | L11: 158 | M11: I | N11: 94.8 | O11: I | P11: 6850 | Q11: I | R11: 38.8 | S11: I
A12: 2022Q3 | B12: 2022 | C12: Q3 | D12: 26.4 | E12: I | F12: 14.7 | G12: I | H12: 15.2 | I12: I | J12: 6.2 | K12: I | L12: 155 | M12: I | N12: 95.5 | O12: I | P12: 6980 | Q12: I | R12: 41.9 | S12: I
A13: 2022Q4 | B13: 2022 | C13: Q4 | D13: 26.5 | E13: I | F13: 15 | G13: I | H13: 15.3 | I13: I | J13: 6.6 | K13: I | L13: 153 | M13: I | N13: 96 | O13: I | P13: 7120 | Q13: I | R13: 47.9 | S13: I
... A25: 2025Q4 | B25: 2025 | C25: Q4 | D25: 31.2 | E25: R | F25: 19.9 | G25: R | H25: 19.3 | I25: R | J25: 15 | K25: R | L25: 158 | M25: R | N25: 99.5 | O25: R | P25: 8650 | Q25: E | R25: 72.9 | S25: E

Sheet Leading_Indicators
A1: Period_ID | B1: Year | C1: Quarter | D1: Period_Type | E1: CAC_Proxy_GHS | F1: CAC_Flag | G1: Network_Utilization_Pct | H1: NetUtil_Flag | I1: Data_Session_Failure_Pct | J1: DSF_Flag | K1: MoMo_Trans_Per_User_Monthly | L1: MoMoTrans_Flag | M1: SIM_Activation_Index | N1: SIM_Flag | O1: Working_Capital_Days | P1: WC_Flag | Q1: Receivables_Days | R1: Recv_Flag | S1: Cedi_USD_Rate_Avg | T1: FX_Flag | U1: Inflation_YoY_Pct | V1: Infl_Flag | W1: Policy_Rate_Pct | X1: Rate_Flag
A2: 2020Q1 | B2: 2020 | C2: Q1 | D2: Quarter | E2: 42 | F2: P | G2: 58 | H2: P | I2: 3.5 | J2: P | K2: 18 | L2: P | M2: 100 | N2: P | O2: 28 | P2: E | Q2: 32 | R2: E | S2: 5.65 | T2: R | U2: 7.8 | V2: R | W2: 16 | X2: R
A3: 2020Q4 | B3: 2020 | C3: Q4 | D3: Quarter | E3: 45 | F3: P | G3: 62 | H3: P | I3: 3.2 | J3: P | K3: 22 | L3: P | M3: 108 | N3: P | O3: 30 | P3: E | Q3: 34 | R3: E | S3: 5.8 | T3: R | U3: 10.4 | V3: R | W3: 14.5 | X3: R
A4: 2021Q2 | B4: 2021 | C4: Q2 | D4: Quarter | E4: 48 | F4: P | G4: 65 | H4: P | I4: 3 | J4: P | K4: 26 | L4: P | M4: 115 | N4: P | O4: 29 | P4: E | Q4: 33 | R4: E | S4: 5.95 | T4: R | U4: 7.8 | V4: R | W4: 13.5 | X4: R
A5: 2021Q4 | B5: 2021 | C5: Q4 | D5: Quarter | E5: 52 | F5: P | G5: 68 | H5: P | I5: 2.8 | J5: P | K5: 30 | L5: P | M5: 122 | N5: P | O5: 31 | P5: E | Q5: 35 | R5: E | S5: 6.1 | T5: R | U5: 12.6 | V5: R | W5: 14.5 | X5: R
A6: 2022Q2 | B6: 2022 | C6: Q2 | D6: Quarter | E6: 58 | F6: P | G6: 71 | H6: P | I6: 2.7 | J6: P | K6: 34 | L6: P | M6: 128 | N6: P | O6: 33 | P6: E | Q6: 38 | R6: E | S6: 8.45 | T6: R | U6: 29.8 | V6: R | W6: 19 | X6: R
A7: 2022Q4 | B7: 2022 | C7: Q4 | D7: Quarter | E7: 68 | F7: P | G7: 73 | H7: P | I7: 2.9 | J7: P | K7: 38 | L7: P | M7: 132 | N7: P | O7: 38 | P7: E | Q7: 42 | R7: E | S7: 12.85 | T7: R | U7: 54.1 | V7: R | W7: 27 | X7: R
A8: 2023Q2 | B8: 2023 | C8: Q2 | D8: Quarter | E8: 72 | F8: P | G8: 74 | H8: P | I8: 2.6 | J8: P | K8: 42 | L8: P | M8: 135 | N8: P | O8: 36 | P8: E | Q8: 40 | R8: E | S8: 11.2 | T8: R | U8: 42.5 | V8: R | W8: 29.5 | X8: R
A9: 2023Q4 | B9: 2023 | C9: Q4 | D9: Quarter | E9: 75 | F9: P | G9: 76 | H9: P | I9: 2.4 | J9: P | K9: 46 | L9: P | M9: 138 | N9: P | O9: 34 | P9: E | Q9: 38 | R9: E | S9: 11.85 | T9: R | U9: 23.2 | V9: R | W9: 30 | X9: R
A10: 2024Q2 | B10: 2024 | C10: Q2 | D10: Quarter | E10: 78 | F10: P | G10: 78 | H10: P | I10: 2.3 | J10: P | K10: 52 | L10: P | M10: 142 | N10: P | O10: 33 | P10: E | Q10: 36 | R10: E | S10: 14.65 | T10: R | U10: 22.8 | V10: R | W10: 29 | X10: R
A11: 2024Q4 | B11: 2024 | C11: Q4 | D11: Quarter | E11: 82 | F11: P | G11: 80 | H11: P | I11: 2.2 | J11: P | K11: 58 | L11: P | M11: 148 | N11: P | O11: 32 | P11: E | Q11: 35 | R11: E | S11: 14.95 | T11: R | U11: 23.8 | V11: R | W11: 27 | X11: R
A12: 2025Q1 | B12: 2025 | C12: Q1 | D12: Quarter | E12: 78 | F12: P | G12: 79 | H12: P | I12: 2 | J12: P | K12: 62 | L12: P | M12: 155 | N12: P | O12: 30 | P12: E | Q12: 33 | R12: E | S12: 14.5 | T12: R | U12: 23.5 | V12: R | W12: 27 | X12: R
A13: 2025Q2 | B13: 2025 | C13: Q2 | D13: Quarter | E13: 75 | F13: P | G13: 80 | H13: P | I13: 1.9 | J13: P | K13: 68 | L13: P | M13: 162 | N13: P | O13: 28 | P13: E | Q13: 31 | R13: E | S13: 12.2 | T13: R | U13: 13.7 | V13: R | W13: 21.5 | X13: R
... A15: 2025Q4 | B15: 2025 | C15: Q4 | D15: Quarter | E15: 70 | F15: P | G15: 82 | H15: P | I15: 1.7 | J15: P | K15: 76 | L15: P | M15: 174 | N15: P | O15: 25 | P15: E | Q15: 28 | R15: E | S15: 8.85 | T15: R | U15: 5.4 | V15: R | W15: 16 | X15: R

Sheet Macro_Context
A1: Period_ID | B1: Year | C1: Period_Type | D1: GDP_Growth_Pct | E1: Inflation_YoY_Pct | F1: Policy_Rate_Pct | G1: Cedi_USD_Avg | H1: Cedi_USD_YoY_Change_Pct | I1: Telecom_Sector_GDP_Share_Pct | J1: Mobile_Penetration_Pct | K1: Data_Penetration_Pct
A2: 2020FY | B2: 2020 | C2: Annual | D2: 0.5 | E2: 9.9 | F2: 14.5 | G2: 5.73 | H2: -3.5 | I2: 2.4 | J2: 134 | K2: 52
A3: 2021FY | B3: 2021 | C3: Annual | D3: 5.4 | E3: 12.6 | F3: 14.5 | G3: 5.95 | H3: -3.8 | I3: 2.5 | J3: 140 | K3: 58
A4: 2022FY | B4: 2022 | C4: Annual | D4: 3.1 | E4: 54.1 | F4: 27 | G4: 8.95 | H4: -50.4 | I4: 2.6 | J4: 143 | K4: 64
A5: 2023FY | B5: 2023 | C5: Annual | D5: 2.9 | E5: 23.2 | F5: 30 | G5: 11.5 | H5: -28.5 | I5: 2.8 | J5: 145 | K5: 68
A6: 2024FY | B6: 2024 | C6: Annual | D6: 5.7 | E6: 23.8 | F6: 27 | G6: 14.8 | H6: -28.7 | I6: 3 | J6: 148 | K6: 72
A7: 2025FY | B7: 2025 | C7: Annual | D7: 6.5 | E7: 5.4 | F7: 16 | G7: 11.6 | H7: 21.6 | I7: 3.3 | J7: 151 | K7: 76

Sheet Derived_Ratios
A1: Period_ID | B1: Year | C1: Period_Type | D1: Revenue_Growth_YoY_Pct | E1: Cost_Growth_YoY_Pct | F1: Cost_Revenue_Ratio_Pct | G1: Opex_to_Revenue_Pct | H1: EBITDA_Margin_Pct | I1: PAT_Margin_Pct | J1: Capex_Intensity_Pct | K1: Subs_Growth_YoY_Pct | L1: Data_Subs_Growth_Pct | M1: MoMo_Subs_Growth_Pct | N1: Data_Rev_Growth_YoY_Pct | O1: MoMo_Rev_Growth_YoY_Pct | P1: Digital_Rev_Growth_YoY_Pct | Q1: Voice_Rev_Growth_YoY_Pct | R1: ARPU_Growth_YoY_Pct | S1: Data_Share_Pct | T1: MoMo_Share_Pct | U1: Voice_Share_Pct | V1: Digital_Share_Pct | W1: Overall_KRI_Score
A2: 2020FY | B2: 2020 | C2: Annual | G2: 47.2 | H2: 54.7 | I2: 22.7 | J2: 21.9 | S2: 33 | T2: 15.8 | U2: 42.4 | V2: 0.9
A3: 2021FY | B3: 2021 | C3: Annual | D3: 40 | E3: 33.3 | F3: 83.2 | G3: 44.9 | H3: 55.6 | I3: 25.3 | J3: 21.8 | K3: 6.6 | L3: 18.4 | M3: 14.1 | N3: 58.8 | O3: 77 | P3: 86.9 | Q3: 20.9 | R3: 30.9 | S3: 37.5 | T3: 20 | U3: 36.6 | V3: 1.3 | W3: Green
A4: 2022FY | B4: 2022 | C4: Annual | D4: 44.4 | E4: 46.1 | F4: 103.7 | G4: 45.5 | H4: 56.9 | I4: 27.4 | J4: 20.2 | K4: 3.1 | L4: 11.1 | M4: 4.8 | N4: 67.7 | O4: 56.1 | P4: 83.3 | Q4: 27 | R4: 39.7 | S4: 43.5 | T4: 21.6 | U4: 32.2 | V4: 1.6 | W4: Amber
A5: 2023FY | B5: 2023 | C5: Annual | D5: 37.7 | E5: 38.4 | F5: 101.9 | G5: 45.7 | H5: 56.7 | I5: 27.9 | J5: 19 | K5: 2.6 | L5: 6.7 | M5: 2.6 | N5: 47.3 | O5: 61 | P5: 81.3 | Q5: 1.3 | R5: 34.3 | S5: 46.6 | T5: 25.3 | U5: 23.7 | V5: 2.1 | W5: Green
A6: 2024FY | B6: 2024 | C6: Annual | D6: 33.5 | E6: 37.4 | F6: 111.6 | G6: 47 | H6: 57.1 | I6: 28.6 | J6: 20.4 | K6: 4.8 | L6: 9.4 | M6: 9.6 | N6: 43.9 | O6: 43.3 | P6: 99.2 | Q6: -11.8 | R6: 27.4 | S6: 50.2 | T6: 27.1 | U6: 15.6 | V6: 3.2 | W6: Amber
A7: 2025FY | B7: 2025 | C7: Annual | D7: 36.2 | E7: 7.7 | F7: 21.3 | G7: 49.6 | H7: 60.1 | I7: 32 | J7: 22.7 | K7: 9.5 | L7: 13.7 | M7: 12.2 | N7: 6.9 | O7: -7.5 | P7: -45.7 | Q7: 7.5 | R7: -4.2 | S7: 52.6 | T7: 24.6 | U7: 16.5 | V7: 1.7 | W7: Green

Sheet Thresholds
A1: KRI_Category | B1: KRI_Name | C1: Unit | D1: Green_Threshold | E1: Amber_Threshold | F1: Red_Threshold | G1: Direction | H1: Indicator_Type | I1: Source_Sheet | J1: Source_Field
A2: Financial | B2: Service Revenue Growth YoY | C2: % | D2: >25 | E2: 15-25 | F2: <15 | G2: Higher_Better | H2: Lagging | I2: Annual | J2: Service_Rev_Growth_Pct
A3: Financial | B3: EBITDA Margin | C3: % | D3: >55 | E3: 50-55 | F3: <50 | G3: Higher_Better | H3: Lagging | I3: Annual | J3: EBITDA_Margin_Pct
A4: Financial | B4: EBITDA Growth YoY | C4: % | D4: >25 | E4: 15-25 | F4: <15 | G4: Higher_Better | H4: Lagging | I4: Annual | J4: EBITDA_Growth_Pct
A5: Financial | B5: PAT Growth YoY | C5: % | D5: >30 | E5: 20-30 | F5: <20 | G5: Higher_Better | H5: Lagging | I5: Annual | J5: PAT_Growth_Pct
A6: Financial | B6: PAT Margin | C6: % | D6: >25 | E6: 20-25 | F6: <20 | G6: Higher_Better | H6: Lagging | I6: Annual | J6: PAT_Margin_Pct
A7: Financial | B7: Cost vs Revenue Growth Ratio | C7: % | D7: <80 | E7: 80-100 | F7: >100 | G7: Lower_Better | H7: Lagging | I7: Derived_Ratios | J7: Cost_Revenue_Ratio
A8: Financial | B8: Capex Intensity | C8: % | D8: 20-25 | E8: 15-20 or 25-30 | F8: <15 or >30 | G8: Range | H8: Lagging | I8: Annual | J8: Capex_Intensity_Pct
A9: Financial | B9: EPS Growth YoY | C9: % | D9: >30 | E9: 20-30 | F9: <20 | G9: Higher_Better | H9: Lagging | I9: Annual | J9: EPS_Growth_Pct
A10: Segment | B10: Data Revenue Growth | C10: % | D10: >40 | E10: 25-40 | F10: <25 | G10: Higher_Better | H10: Lagging | I10: Segments_Annual | J10: Data_Growth_Pct
A11: Segment | B11: Data Share of Revenue | C11: % | D11: >50 | E11: 45-50 | F11: <45 | G11: Higher_Better | H11: Lagging | I11: Segments_Annual | J11: Data_Share_Pct
A12: Segment | B12: MoMo Revenue Growth | C12: % | D12: >35 | E12: 20-35 | F12: <20 | G12: Higher_Better | H12: Lagging | I12: Segments_Annual | J12: MoMo_Growth_Pct
... A29: Leading | B29: Inflation YoY | C29: % | D29: <15 | E29: 15-25 | F29: >25 | G29: Lower_Better | H29: Leading | I29: Macro_Context | J29: Inflation_YoY_Pct
